Workbook

Sheet BASE_DEDADOS
A1: Data | B1: km_rodado | C1: Qtde_entregas | D1: Receita | E1: Incentivo | F1: Vale_gasolina | G1: Combustível | H1: Manutenção | I1: Pedagio | J1: Receita_bruta_total | K1: Despesa_operacional | L1: Lucro_operacional | M1: Receita_por_entrega | N1: Custo_por_entrega | O1: EXIBIR
A2: 46020 | B2: 58 | C2: 59 | D2: 236 | F2: =IF(B2>60,B2*1,IF(B2>=40,B2*0.7,B2*0.4)) -> 40.6 | G2: 25.71 | H2: 95 | J2: =D2+E2+F2+I2 -> 276.6 | K2: =G2+H2+I2 -> 120.71 | L2: =J2-K2 -> 155.89 | M2: =J2/C2 -> 4.6881356 | N2: =IFERROR(K2/C2,0) -> 2.0459322 | O2: =IF(L2=0,"","OK") -> OK
A3: 46021 | B3: 34 | C3: 38 | D3: 152 | F3: =IF(B3>60,B3*1,IF(B3>=40,B3*0.7,B3*0.4)) -> 13.6 | G3: 25.71 | J3: =D3+E3+F3+I3 -> 165.6 | K3: =G3+H3+I3 -> 25.71 | L3: =J3-K3 -> 139.89 | M3: =J3/C3 -> 4.3578947 | N3: =IFERROR(K3/C3,0) -> 0.67657895 | O3: =IF(L3=0,"","OK") -> OK
A4: 46022 | F4: =IF(B4>60,B4*1,IF(B4>=40,B4*0.7,B4*0.4)) -> 0 | J4: =D4+E4+F4+I4 -> 0 | K4: =G4+H4+I4 -> 0 | L4: =J4-K4 -> 0 | M4: =IFERROR(J4/C4,0) -> 0 | N4: =IFERROR(K4/C4,0) -> 0 | O4: =IF(L4=0,"","OK")
A5: 46023 | F5: =IF(B5>60,B5*1,IF(B5>=40,B5*0.7,B5*0.4)) -> 0 | J5: =D5+E5+F5+I5 -> 0 | K5: =G5+H5+I5 -> 0 | L5: =J5-K5 -> 0 | M5: =IFERROR(J5/C5,) -> 0 | N5: =IFERROR(K5/C5,0) -> 0 | O5: =IF(L5=0,"","OK")
A6: 46024 | F6: =IF(B6>60,B6*1,IF(B6>=40,B6*0.7,B6*0.4)) -> 0 | J6: =D6+E6+F6+I6 -> 0 | K6: =G6+H6+I6 -> 0 | L6: =J6-K6 -> 0 | M6: =IFERROR(J6/C6,0) -> 0 | N6: =IFERROR(K6/C6,0) -> 0 | O6: =IF(L6=0,"","OK")
A7: 46025 | B7: 54 | C7: 92 | D7: 368 | E7: 70 | F7: =IF(B7>60,B7*1,IF(B7>=40,B7*0.7,B7*0.4)) -> 37.8 | G7: 25.71 | J7: =D7+E7+F7+I7 -> 475.8 | K7: =G7+H7+I7 -> 25.71 | L7: =J7-K7 -> 450.09 | M7: =J7/C7 -> 5.1717391 | N7: =IFERROR(K7/C7,0) -> 0.27945652 | O7: =IF(L7=0,"","OK") -> OK
A8: 46026 | F8: =IF(B8>60,B8*1,IF(B8>=40,B8*0.7,B8*0.4)) -> 0 | J8: =D8+E8+F8+I8 -> 0 | K8: =G8+H8+I8 -> 0 | L8: =J8-K8 -> 0 | M8: =IFERROR(J8/C8,0) -> 0 | N8: =IFERROR(K8/C8,0) -> 0 | O8: =IF(L8=0,"","OK")
A9: 46027 | B9: 34 | C9: 80 | D9: 320 | F9: =IF(B9>60,B9*1,IF(B9>=40,B9*0.7,B9*0.4)) -> 13.6 | G9: 25.71 | J9: =D9+E9+F9+I9 -> 333.6 | K9: =G9+H9+I9 -> 25.71 | L9: =J9-K9 -> 307.89 | M9: =J9/C9 -> 4.17 | N9: =IFERROR(K9/C9,0) -> 0.321375 | O9: =IF(L9=0,"","OK") -> OK
A10: 46028 | B10: 37 | C10: 35 | D10: 140 | E10: 70 | F10: =IF(B10>60,B10*1,IF(B10>=40,B10*0.7,B10*0.4)) -> 14.8 | G10: 25.71 | J10: =D10+E10+F10+I10 -> 224.8 | K10: =G10+H10+I10 -> 25.71 | L10: =J10-K10 -> 199.09 | M10: =J10/C10 -> 6.4228571 | N10: =IFERROR(K10/C10,0) -> 0.73457143 | O10: =IF(L10=0,"","OK") -> OK
A11: 46029 | B11: 32 | C11: 99 | D11: 247.5 | F11: =IF(B11>60,B11*1,IF(B11>=40,B11*0.7,B11*0.4)) -> 12.8 | G11: 25.71 | J11: =D11+E11+F11+I11 -> 260.3 | K11: =G11+H11+I11 -> 25.71 | L11: =J11-K11 -> 234.59 | M11: =J11/C11 -> 2.6292929 | N11: =IFERROR(K11/C11,0) -> 0.25969697 | O11: =IF(L11=0,"","OK") -> OK
A12: 46030 | B12: 71 | C12: 19 | D12: 200 | F12: =IF(B12>60,B12*1,IF(B12>=40,B12*0.7,B12*0.4)) -> 71 | G12: 25.71 | J12: =D12+E12+F12+I12 -> 271 | K12: =G12+H12+I12 -> 25.71 | L12: =J12-K12 -> 245.29 | M12: =J12/C12 -> 14.263158 | N12: =IFERROR(K12/C12,0) -> 1.3531579 | O12: =IF(L12=0,"","OK") -> OK
A13: 46031 | F13: =IF(B13>60,B13*1,IF(B13>=40,B13*0.7,B13*0.4)) -> 0 | J13: =D13+E13+F13+I13 -> 0 | K13: =G13+H13+I13 -> 0 | L13: =J13-K13 -> 0 | M13: =IFERROR(J13/C13,0) -> 0 | N13: =IFERROR(K13/C13,0) -> 0 | O13: =IF(L13=0,"","OK")
A14: 46032 | B14: 37 | C14: 35 | D14: 140 | E14: 70 | F14: =IF(B14>60,B14*1,IF(B14>=40,B14*0.7,B14*0.4)) -> 14.8 | G14: 25.71 | J14: =D14+E14+F14+I14 -> 224.8 | K14: =G14+H14+I14 -> 25.71 | L14: =J14-K14 -> 199.09 | M14: =J14/C14 -> 6.4228571 | N14: =IFERROR(K14/C14,0) -> 0.73457143 | O14: =IF(L14=0,"","OK") -> OK
A15: 46033 | F15: =IF(B15>60,B15*1,IF(B15>=40,B15*0.7,B15*0.4)) -> 0 | J15: =D15+E15+F15+I15 -> 0 | K15: =G15+H15+I15 -> 0 | L15: =J15-K15 -> 0 | M15: =IFERROR(J15/C15,0) -> 0 | N15: =IFERROR(K15/C15,0) -> 0 | O15: =IF(L15=0,"","OK") | Q15: FALSE
A16: 46034 | B16: 38 | C16: 54 | D16: 216 | F16: =IF(B16>60,B16*1,IF(B16>=40,B16*0.7,B16*0.4)) -> 15.2 | G16: 25.71 | J16: =D16+E16+F16+I16 -> 231.2 | K16: =G16+H16+I16 -> 25.71 | L16: =J16-K16 -> 205.49 | M16: =J16/C16 -> 4.2814815 | N16: =IFERROR(K16/C16,0) -> 0.47611111 | O16: =IF(L16=0,"","OK") -> OK
A17: 46035 | F17: =IF(B17>60,B17*1,IF(B17>=40,B17*0.7,B17*0.4)) -> 0 | J17: =D17+E17+F17+I17 -> 0 | K17: =G17+H17+I17 -> 0 | L17: =J17-K17 -> 0 | M17: =IFERROR(J17/C17,0) -> 0 | N17: =IFERROR(K17/C17,0) -> 0 | O17: =IF(L17=0,"","OK")
A18: 46036 | B18: 45 | C18: 10 | D18: 80 | F18: =IF(B18>60,B18*1,IF(B18>=40,B18*0.7,B18*0.4)) -> 31.5 | G18: 25.71 | J18: =D18+E18+F18+I18 -> 111.5 | K18: =G18+H18+I18 -> 25.71 | L18: =J18-K18 -> 85.79 | M18: =J18/C18 -> 11.15 | N18: =IFERROR(K18/C18,0) -> 2.571 | O18: =IF(L18=0,"","OK") -> OK
A19: 46037 | F19: =IF(B19>60,B19*1,IF(B19>=40,B19*0.7,B19*0.4)) -> 0 | J19: =D19+E19+F19+I19 -> 0 | K19: =G19+H19+I19 -> 0 | L19: =J19-K19 -> 0 | M19: =IFERROR(J19/C19,0) -> 0 | N19: =IFERROR(K19/C19,0) -> 0 | O19: =IF(L19=0,"","OK")
A20: 46038 | B20: 21 | C20: 21 | D20: 84 | F20: =IF(B20>60,B20*1,IF(B20>=40,B20*0.7,B20*0.4)) -> 8.4 | G20: 25.71 | H20: 95 | J20: =D20+E20+F20+I20 -> 92.4 | K20: =G20+H20+I20 -> 120.71 | L20: =J20-K20 -> -28.31 | M20: =J20/C20 -> 4.4 | N20: =IFERROR(K20/C20,0) -> 5.7480952 | O20: =IF(L20=0,"","OK") -> OK
A21: 46039 | F21: =IF(B21>60,B21*1,IF(B21>=40,B21*0.7,B21*0.4)) -> 0 | J21: =D21+E21+F21+I21 -> 0 | K21: =G21+H21+I21 -> 0 | L21: =J21-K21 -> 0 | M21: =IFERROR(J21/C21,0) -> 0 | N21: =IFERROR(K21/C21,0) -> 0 | O21: =IF(L21=0,"","OK")
A22: 46040 | F22: =IF(B22>60,B22*1,IF(B22>=40,B22*0.7,B22*0.4)) -> 0 | J22: =D22+E22+F22+I22 -> 0 | K22: =G22+H22+I22 -> 0 | L22: =J22-K22 -> 0 | M22: =IFERROR(J22/C22,0) -> 0 | N22: =IFERROR(K22/C22,0) -> 0 | O22: =IF(L22=0,"","OK")
A23: 46041 | B23: 31 | C23: 5 | D23: 80 | F23: =IF(B23>60,B23*1,IF(B23>=40,B23*0.7,B23*0.4)) -> 12.4 | G23: 25.71 | J23: =D23+E23+F23+I23 -> 92.4 | K23: =G23+H23+I23 -> 25.71 | L23: =J23-K23 -> 66.69 | M23: =J23/C23 -> 18.48 | N23: =IFERROR(K23/C23,0) -> 5.142 | O23: =IF(L23=0,"","OK") -> OK
A24: 46042 | F24: =IF(B24>60,B24*1,IF(B24>=40,B24*0.7,B24*0.4)) -> 0 | J24: =D24+E24+F24+I24 -> 0 | K24: =G24+H24+I24 -> 0 | L24: =J24-K24 -> 0 | M24: =IFERROR(J24/C24,0) -> 0 | N24: =IFERROR(K24/C24,0) -> 0 | O24: =IF(L24=0,"","OK")
A25: 46043 | B25: 55 | C25: 78 | D25: 312 | F25: =IF(B25>60,B25*1,IF(B25>=40,B25*0.7,B25*0.4)) -> 38.5 | G25: 25.71 | J25: =D25+E25+F25+I25 -> 350.5 | K25: =G25+H25+I25 -> 25.71 | L25: =J25-K25 -> 324.79 | M25: =J25/C25 -> 4.4935897 | N25: =IFERROR(K25/C25,0) -> 0.32961538 | O25: =IF(L25=0,"","OK") -> OK
A26: 46044 | B26: 48 | C26: 42 | D26: 172 | F26: =IF(B26>60,B26*1,IF(B26>=40,B26*0.7,B26*0.4)) -> 33.6 | G26: 25.71 | J26: =D26+E26+F26+I26 -> 205.6 | K26: =G26+H26+I26 -> 25.71 | L26: =J26-K26 -> 179.89 | M26: =J26/C26 -> 4.8952381 | N26: =IFERROR(K26/C26,0) -> 0.61214286 | O26: =IF(L26=0,"","OK") -> OK
A27: 46045 | B27: 15 | C27: 2 | D27: 80 | E27: 70 | F27: =IF(B27>60,B27*1,IF(B27>=40,B27*0.7,B27*0.4)) -> 6 | G27: 25.71 | J27: =D27+E27+F27+I27 -> 156 | K27: =G27+H27+I27 -> 25.71 | L27: =J27-K27 -> 130.29 | M27: =J27/C27 -> 78 | N27: =IFERROR(K27/C27,0) -> 12.855 | O27: =IF(L27=0,"","OK") -> OK
A28: 46046 | F28: =IF(B28>60,B28*1,IF(B28>=40,B28*0.7,B28*0.4)) -> 0 | J28: =D28+E28+F28+I28 -> 0 | K28: =G28+H28+I28 -> 0 | L28: =J28-K28 -> 0 | M28: =IFERROR(J28/C28,0) -> 0 | N28: =IFERROR(K28/C28,0) -> 0 | O28: =IF(L28=0,"","OK")
A29: 46047 | F29: =IF(B29>60,B29*1,IF(B29>=40,B29*0.7,B29*0.4)) -> 0 | J29: =D29+E29+F29+I29 -> 0 | K29: =G29+H29+I29 -> 0 | L29: =J29-K29 -> 0 | M29: =IFERROR(J29/C29,0) -> 0 | N29: =IFERROR(K29/C29,0) -> 0 | O29: =IF(L29=0,"","OK")
A30: 46048 | B30: 36 | C30: 63 | D30: 252 | F30: =IF(B30>60,B30*1,IF(B30>=40,B30*0.7,B30*0.4)) -> 14.4 | G30: 25.71 | J30: =D30+E30+F30+I30 -> 266.4 | K30: =G30+H30+I30 -> 25.71 | L30: =J30-K30 -> 240.69 | M30: =J30/C30 -> 4.2285714 | N30: =IFERROR(K30/C30,0) -> 0.40809524 | O30: =IF(L30=0,"","OK") -> OK
A31: 46049 | B31: 72 | C31: 98 | D31: 392 | F31: =IF(B31>60,B31*1,IF(B31>=40,B31*0.7,B31*0.4)) -> 72 | G31: 25.71 | I31: 2.7 | J31: =D31+E31+F31+I31 -> 466.7 | K31: =G31+H31+I31 -> 28.41 | L31: =J31-K31 -> 438.29 | M31: =J31/C31 -> 4.7622449 | N31: =IFERROR(K31/C31,0) -> 0.28989796 | O31: =IF(L31=0,"","OK") -> OK
A32: 46050 | B32: 81 | C32: 82 | D32: 328 | F32: =IF(B32>60,B32*1,IF(B32>=40,B32*0.7,B32*0.4)) -> 81 | G32: 25.71 | J32: =D32+E32+F32+I32 -> 409 | K32: =G32+H32+I32 -> 25.71 | L32: =J32-K32 -> 383.29 | M32: =J32/C32 -> 4.9878049 | N32: =IFERROR(K32/C32,0) -> 0.31353659 | O32: =IF(L32=0,"","OK") -> OK
A33: 46051 | B33: 72 | C33: 98 | D33: 392 | F33: =IF(B33>60,B33*1,IF(B33>=40,B33*0.7,B33*0.4)) -> 72 | G33: 25.71 | I33: 2.7 | J33: =D33+E33+F33+I33 -> 466.7 | K33: =G33+H33+I33 -> 28.41 | L33: =J33-K33 -> 438.29 | M33: =J33/C33 -> 4.7622449 | N33: =IFERROR(K33/C33,0) -> 0.28989796 | O33: =IF(L33=0,"","OK") -> OK

Sheet RESUMO
A1: INDICADORES OPERACIONAIS | D1: DRE SIMPLIFICADA
A2: INDICADOR | B2: VALOR | D2: INDICADOR | E2: VALOR
A3: RECEITA_BRUTA_TOTAL | B3: =SUM(BASE_DEDADOS!J:J) -> 5080.9 | D3: Receita Bruta Total | E3: =SUM(BASE_DEDADOS!J2:J33) -> 5080.9
A4: DESPESA_OPERACIONAL | B4: =SUM(BASE_DEDADOS!K:K) -> 683.89 | D4: (-) Despesa operacional | E4: =SUM(BASE_DEDADOS!K:K) -> 683.89
A5: LUCRO_OPERACIONAL | B5: =SUM(BASE_DEDADOS!L:L) -> 4397.01 | D5: Lucro operacional | E5: =SUM(BASE_DEDADOS!L:L) -> 4397.01
A6: QTD_ENTREGAS | B6: =SUM(BASE_DEDADOS!C:C) -> 1010 | D6: (-) DAS-imposto MEI | E6: 80
A7: TICKET_MÉDIO | B7: =B3/B6 -> 5.0305941 | D7: (-) Parcela financiamento moto | E7: 705
A8: CUSTO_MÉDIO_POR_ENTREGA | B8: =B4/B6 -> 0.67711881 | D8: Resultado liquído disponível | E8: =E5-E6-E7 -> 3612.01
A9: LUCRO_MÉDIO_POR_ENTREGA | B9: =B5/B6 -> 4.3534752
A11: MARGEM (%)
A12: INDICADOR | B12: VALOR | C12: (%)
A13: Receita bruta total | B13: =SUM(Tabela1[[#All],[Receita_bruta_total]]) -> 5080.9 | C13: =B13/B13 -> 1
A14: (-) Despesa Operacional | B14: =SUM(BASE_DEDADOS!K:K) -> 683.89 | C14: =B14/B13 -> 0.13460017
A15: Margem operacional | B15: =SUM(Tabela1[[#All],[Lucro_operacional]]) -> 4397.01 | C15: =B15/B13 -> 0.86539983
A16: (-) DAS | B16: 80 | C16: =B16/B13 -> 0.015745242
A17: (-) Parcela moto | B17: 705 | C17: =B17/B13 -> 0.13875494
A18: Margem liquída | B18: =B13-B14-B16-B17 -> 3612.01 | C18: =B18/B13 -> 0.71089964
A20: COMPOSIÇÃO DAS DESPESAS OPERACIONAL
A21: INDICADOR | B21: VALOR | C21: (%)
A22: Combustível | B22: =SUM(Tabela1[[#All],[Combustível]]) -> 488.49 | C22: =B22/B25 -> 0.71428154
A23: Manutenção | B23: =SUM(Tabela1[[#All],[Manutenção]]) -> 190 | C23: =B23/B25 -> 0.27782246
A24: Pedagio | B24: =SUM(Tabela1[[#All],[Pedagio]]) -> 5.4 | C24: =B24/B25 -> 0.0078960067
A25: Despesa total | B25: =SUM(Tabela1[[#All],[Despesa_operacional]]) -> 683.89 | C25: =B25/B25 -> 1
A27: EFICIÊNCIA POR KM RODADO
A28: INDICADOR | B28: VALOR
A29: total km rodado | B29: =SUM(Tabela1[km_rodado]) -> 871
A30: Receita por km | B30: =E3/B29 -> 5.8334099
A31: Custo por km | B31: =E4/B29 -> 0.78517796
A32: Lucro por km | B32: =E5/B29 -> 5.0482319
A33: Indice de eficiência | B33: =B32/B30 -> 0.86539983
A35: COMPOSIÇÃO DA RECEITA
A36: INDICADOR | B36: VALOR | C36: (%)
A37: Receita por entrega | B37: =SUM(Tabela1[Receita]) -> 4191.5 | C37: =B37/E3 -> 0.82495227
A38: Incentivos recebidos | B38: =SUM(Tabela1[Incentivo]) -> 280 | C38: =B38/E3 -> 0.055108347
A39: Vale gasolina | B39: =SUM(Tabela1[Vale_gasolina]) -> 604 | C39: =B39/E3 -> 0.11887658
A40: Vale pedagio | B40: =SUM(Tabela1[Pedagio]) -> 5.4 | C40: =B40/E3 -> 0.0010628038
A41: Receita bruta total | B41: =SUM(B37:B38:B39:B40) -> 5080.9 | C41: =B41/B41 -> 1
A43: MELHOR DIA / PIOR DIA
A44: INDICADOR | B44: VALOR
A45: Melhor dia (receita/entrega) | B45: =INDEX(BASE_DEDADOS!A2:A33,MATCH(MAX(BASE_DEDADOS!M2:M33),BASE_DEDADOS!M2:M33,0)) -> 46045
...

Sheet DASHBOARD
